{
    "i18n.not_found": "The translation value corresponding to key ${name} was not found. Please check if the translation file is complete.",
    "main.info.python_version": "The Python version you are using is ${major}.${minor}.${patch},",
    "main.info.supported_version": "but this program requires the use of Python version 3.9 or above, please replace it in a timely manner.",
    "init.info.checking": "Performing pre-running checks...",
    "init.info.running_with_cert": "Starting main control with certificates...",
    "init.info.running_without_cert": "Starting main control without certificates...",
    "init.info.service_port": "Server listening on ${port}.",
    "init.info.reset_data": "The data has been reset.",
    "init.warning.received_report": "Received report, redirect record: ${urls}, error message: ${error}",
    "init.info.stoped": "The main control has been successfully closed.",
    "utils.info.calculate_filelist": "The file list calculation was successful and has been saved locally.",
    "upstream.info.fetch_git_repo": "正在同步 ${url} 远程仓库",
    "upstream.info.fetch_git_repo_success": "远程仓库 ${url} 同步完成",
    "response.400.unsupported_media_type": "Unsupported Media Type",
    "response.401.no_permission": "No Permission",
    "response.401.no_auth": "No Authorization",
    "response.403.node_is_banned": "Node is banned, reason: ${reason}",
    "response.404.not_found": "Not Found",
    "response.404.node_not_found": "Node Not Found",
    "socketio.debug.connect_failed_token": "Client ${sid} connection failed (reason: token not submitted)",
    "socketio.debug.connect_failed_authentication": "Client ${sid} connection failed (reason: authentication error)",
    "socketio.message.welcome": "Welcome to iodine@home, this project is already at https://github.com/ZeroNexis/iodine-at-home open source and looks forward to your contributions and support.",
    "socketio.debug.disconnect": "客户端 ${sid} 断开了连接",
    "socketio.debug.abnormal_disconnect": "${sid} disconnected abnormally and has been removed from the online node list",
    "socketio.return.node_not_found": "错误: 节点似乎并不存在，请检查配置文件",
    "socketio.return.node_is_online": "ERROR: Node is already online, please check configuration file",
    "socketio.message.version_tips": "The current version is outdated, it is recommended to upgrade to version v${version} or higher.",
    "socketio.debug.enable": "Node ${id} goes online (measured bandwidth: ${bandwidth})",
    "socketio.message.trust_low": "Node trust is too low. Please keep it stable online.",
    "socketio.debug.measure_low": "${id} 测速未通过（测量带宽: {bandwidth}）",
    "socketio.return.measure_low": "错误: 测量带宽小于 10Mbps，（测量得 ${bandwidth}），请重试尝试上线",
    "socketio.debug.measure_error": "${id} 测速未通过（错误: ${bandwidth[1]}）",
    "socketio.return.measure_error": "ERROR: ${bandwidth}",
    "socketio.debug.keep_alive_success": "Node ${id} keeps alive (hits: ${hits} times | requested data: ${bytes})",
    "socketio.debug.disable_failed_not_found": "A node attempted to disable the cluster but failed (reason: node does not exist)",
    "socketio.debug.disable_success": "节点 ${id} 禁用集群",
    "socketio.debug.disable_failed_not_online": "Node ${id} failed to attempt to disable the cluster (reason: node is not enabled)"
}